<?xml version="1.0" encoding="utf-8"?>
<!-- This URDF was automatically created by SolidWorks to URDF Exporter! Originally created by Stephen Brawner (brawner@gmail.com) 
     Commit Version: 1.6.0-1-g15f4949  Build Version: 1.6.7594.29634
     For more information, please see http://wiki.ros.org/sw_urdf_exporter -->
<robot
  name="riltaur"
  xmlns:xacro="http://ros.org/wiki/xacro">

  <xacro:arg name="laser_visual"  default="false"/>
  <xacro:arg name="camera_visual" default="false"/>
  <!-- <xacro:arg name="robot_name" default="robot_1"/> -->

  <gazebo>
    <plugin name="gazebo_ros_control" filename="libgazebo_ros_control.so">
      <robotNamespace>/$(arg robot_name)</robotNamespace>
    </plugin>
  </gazebo>

  <link name="base_footprint">
  </link>

  <link
    name="base_link">
    <inertial>
      <origin
        xyz="-8.9005E-16 3.31E-05 3.4632E-17"
        rpy="0 0 0" />
      <mass
        value="8.0144" />
      <inertia
        ixx="0.022341"
        ixy="-7.5877E-18"
        ixz="-5.7879E-12"
        iyy="0.01977"
        iyz="2.4E-16"
        izz="0.0057527" />
    </inertial>
    <visual>
      <origin
        xyz="0 0 0"
        rpy="0 0 0" />
      <geometry>
        <mesh
          filename="package://riltaur_description/meshes/base_link.STL" />
      </geometry>
      <material
        name="">
        <color
          rgba="0.75294 0.75294 0.75294 1" />
      </material>
    </visual>
    <collision>
      <origin
        xyz="0 0 0"
        rpy="0 0 0" />
      <geometry>
        <mesh
          filename="package://riltaur_description/meshes/base_link.STL" />
      </geometry>
    </collision>
  </link>

  <joint name="joint_base_footprint_to_base_link" type="fixed">
    <parent link="base_footprint"/>
    <child link="base_link"/>
    <origin
      xyz="0.0 0 0.17"
      rpy="0 0 0" />
  </joint>

 





  <xacro:macro name="leg_link" params="name *inertial">
    <link
      name="${name}">
      <xacro:insert_block name="inertial" />
      <visual>
        <origin
          xyz="0 0 0"
          rpy="0 0 0" />
        <geometry>
          <mesh
            filename="package://riltaur_description/meshes/${name}.STL" />
        </geometry>
        <material
          name="">
          <color
            rgba="0.898039215686275 0.917647058823529 0.929411764705882 1" />
        </material>
      </visual>
      <collision>
        <origin
          xyz="0 0 0"
          rpy="0 0 0" />
        <geometry>
          <mesh
            filename="package://riltaur_description/meshes/${name}.STL" />
        </geometry>
        <surface>
          <friction>
            <ode>
              <mu>100000.0</mu>
              <mu2>100000.0</mu2>
            </ode>
          </friction>
        </surface>
      </collision>
    </link>
  </xacro:macro>

  <xacro:macro name="leg_joint" params="name parent child *joint_origin *joint_axis *joint_limits">
    <joint
      name="${name}"
      type="revolute">
      <xacro:insert_block name="joint_origin" />
      <parent
        link="${parent}" />
      <child
        link="${child}" />
      <!-- <axis
        xyz="0 0 1" /> -->
      <xacro:insert_block name="joint_axis" />
      <xacro:insert_block name="joint_limits" />
    </joint>
  </xacro:macro>

  <xacro:macro name="m_transmission" params="tran_name joint_name acutator_name">
    <!-- Transmission at Leg 0 Motor 0 -->
    <transmission name="${tran_name}">
      <type>transmission_interface/SimpleTransmission</type>
      <joint name="${joint_name}">
        <hardwareInterface>hardware_interface/EffortJointInterface</hardwareInterface>
      </joint>
      <actuator name="${acutator_name}">
        <mechanicalReduction>1</mechanicalReduction>
      </actuator>
    </transmission>
  </xacro:macro>






  <!-- Leg 0 Motor 0 Link 1 -->
  <xacro:leg_link name="leg0_motor0_link1">
    <inertial>
      <origin
        xyz="-1.06858966120171E-15 -0.0300110619984783 -0.00493338636036998"
        rpy="0 0 0" />
      <mass
        value="0.0594163548713964" />
      <inertia
        ixx="6.99490427840268E-05"
        ixy="-2.85873619698326E-20"
        ixz="4.15210616661672E-21"
        iyy="6.65712098741484E-06"
        iyz="-1.18781972268197E-07"
        izz="7.56253951362582E-05" />
    </inertial>
  </xacro:leg_link>

  <xacro:leg_link name="leg0_motor0_link2">
    <inertial>
      <origin
        xyz="-5.6205E-16 -0.090625 -0.005"
        rpy="0 0 0" />
      <mass
        value="0.060746" />
      <inertia
        ixx="0.00023567"
        ixy="1.8105E-19"
        ixz="-6.5542E-22"
        iyy="3.3788E-06"
        iyz="1.6828E-19"
        izz="0.00023803" />
    </inertial>
  </xacro:leg_link>

  <xacro:leg_link name="leg0_motor1_link1">
    <inertial>
      <origin
        xyz="2.7756E-17 -0.030011 -0.0049334"
        rpy="0 0 0" />
      <mass
        value="0.059416" />
      <inertia
        ixx="6.9949E-05"
        ixy="-3.8752E-20"
        ixz="-2.1146E-22"
        iyy="6.6571E-06"
        iyz="-1.1878E-07"
        izz="7.5625E-05" />
    </inertial>
  </xacro:leg_link>

  <xacro:leg_link name="leg0_motor1_link2">
    <inertial>
      <origin
        xyz="-5.8287E-15 -0.078043 -0.005"
        rpy="0 0 0" />
      <mass
        value="0.050148" />
      <inertia
        ixx="0.00016137"
        ixy="-1.0757E-19"
        ixz="-4.3558E-22"
        iyy="3.0293E-06"
        iyz="8.1575E-21"
        izz="0.00016356" />
    </inertial>
  </xacro:leg_link>

  <xacro:leg_link name="leg1_motor0_link1">
    <inertial>
      <origin
        xyz="-2.949E-14 -0.029875 0.0049337"
        rpy="0 0 0" />
      <mass
        value="0.059687" />
      <inertia
        ixx="7.0222E-05"
        ixy="6.7763E-20"
        ixz="-2.5802E-21"
        iyy="6.6874E-06"
        iyz="1.1824E-07"
        izz="7.5924E-05" />
    </inertial>
  </xacro:leg_link>

  <xacro:leg_link name="leg1_motor0_link2">
    <inertial>
      <origin
        xyz="-1.67782454596477E-14 -0.0906248237378078 0.00499999999999988"
        rpy="0 0 0" />
      <mass
        value="0.0607457960840249" />
      <inertia
        ixx="0.000235666794197457"
        ixy="1.40925106599434E-19"
        ixz="-3.2988893695327E-21"
        iyy="3.37883026197478E-06"
        iyz="-1.75909126435285E-19"
        izz="0.000238033194524698" />
    </inertial>
  </xacro:leg_link>

  <xacro:leg_link name="leg1_motor1_link1">
    <inertial>
      <origin
        xyz="5.55111512312578E-17 -0.0298751156893431 0.00493368811171915"
        rpy="0 0 0" />
      <mass
        value="0.0596867281891459" />
      <inertia
        ixx="7.02217733717641E-05"
        ixy="-3.55753837846806E-20"
        ixz="9.19276296920642E-22"
        iyy="6.6874391981755E-06"
        iyz="1.18243904980785E-07"
        izz="7.59239353241664E-05" />
    </inertial>
  </xacro:leg_link>

  <xacro:leg_link name="leg1_motor1_link2">
    <inertial>
      <origin
        xyz="-2.4009E-14 -0.078043 0.005"
        rpy="0 0 0" />
      <mass
        value="0.050148" />
      <inertia
        ixx="0.00016137"
        ixy="-1.153E-19"
        ixz="1.9179E-21"
        iyy="3.0293E-06"
        iyz="-1.0566E-20"
        izz="0.00016356" />
    </inertial>
  </xacro:leg_link>

  <xacro:leg_link name="leg2_motor0_link1">
    <inertial>
      <origin
        xyz="1.2687073613904E-12 -0.0300110619995626 -0.00493338636037007"
        rpy="0 0 0" />
      <mass
        value="0.0594163548713964" />
      <inertia
        ixx="6.99490427840269E-05"
        ixy="-6.98284432595789E-16"
        ixz="-1.3117386814E-18"
        iyy="6.65712098741485E-06"
        iyz="-1.18781972268212E-07"
        izz="7.56253951362583E-05" />
    </inertial>
  </xacro:leg_link>

  <xacro:leg_link name="leg2_motor0_link2">
    <inertial>
      <origin
        xyz="2.66467403697845E-13 -0.0906248237379459 -0.00499999999999996"
        rpy="0 0 0" />
      <mass
        value="0.0607457960840249" />
      <inertia
        ixx="0.000235666794197458"
        ixy="3.294467944501E-16"
        ixz="6.56416263916486E-21"
        iyy="3.37883026197468E-06"
        iyz="2.70889422585715E-19"
        izz="0.000238033194524699" />
    </inertial>
  </xacro:leg_link>

  <xacro:leg_link name="leg2_motor1_link1">
    <inertial>
      <origin
        xyz="5.55111512312578E-17 -0.0300110619984791 -0.00493338636037007"
        rpy="0 0 0" />
      <mass
        value="0.0594163548713964" />
      <inertia
        ixx="6.99490427840269E-05"
        ixy="-3.32460431797313E-20"
        ixz="-3.438086130976E-22"
        iyy="6.65712098741485E-06"
        iyz="-1.18781972268187E-07"
        izz="7.56253951362584E-05" />
    </inertial>
  </xacro:leg_link>

  <xacro:leg_link name="leg2_motor1_link2">
    <inertial>
      <origin
        xyz="-8.7985E-14 -0.078043 -0.005"
        rpy="0 0 0" />
      <mass
        value="0.050148" />
      <inertia
        ixx="0.00016137"
        ixy="-2.0663E-15"
        ixz="8.1891E-22"
        iyy="3.0293E-06"
        iyz="4.6235E-20"
        izz="0.00016356" />
    </inertial>
  </xacro:leg_link>

  <xacro:leg_link name="leg3_motor0_link1">
    <inertial>
      <origin
        xyz="2.95347080125907E-13 -0.0300110619987314 0.00493338636037008"
        rpy="0 0 0" />
      <mass
        value="0.0594163548713964" />
      <inertia
        ixx="6.99490427840269E-05"
        ixy="-1.62619526202748E-16"
        ixz="3.04998819376224E-19"
        iyy="6.65712098741487E-06"
        iyz="1.1878197226823E-07"
        izz="7.56253951362583E-05" />
    </inertial>
  </xacro:leg_link>

  <xacro:leg_link name="leg3_motor0_link2">
    <inertial>
      <origin
        xyz="-2.89376651807505E-09 -0.0906248254650945 0.005000000184577"
        rpy="0 0 0" />
      <mass
        value="0.0607457960840251" />
      <inertia
        ixx="0.000235666794197458"
        ixy="-7.09390093325477E-20"
        ixz="-3.14097813925418E-21"
        iyy="3.37883026197477E-06"
        iyz="-5.04270774407783E-20"
        izz="0.000238033194524699" />
    </inertial>
  </xacro:leg_link>

  <xacro:leg_link name="leg3_motor1_link1">
    <inertial>
      <origin
        xyz="2.7756E-17 -0.030011 0.0049334"
        rpy="0 0 0" />
      <mass
        value="0.059416" />
      <inertia
        ixx="6.9949E-05"
        ixy="-4.1505E-20"
        ixz="2.4124E-22"
        iyy="6.6571E-06"
        iyz="1.1878E-07"
        izz="7.5625E-05" />
    </inertial>
  </xacro:leg_link>

  <xacro:leg_link name="leg3_motor1_link2">
    <inertial>
      <origin
        xyz="2.9893E-14 -0.078043 0.005"
        rpy="0 0 0" />
      <mass
        value="0.050148" />
      <inertia
        ixx="0.00016137"
        ixy="7.0356E-16"
        ixz="-3.0653E-21"
        iyy="3.0293E-06"
        iyz="-5.2636E-20"
        izz="0.00016356" />
    </inertial>
  </xacro:leg_link>





  <!-- Leg 0 Motor 0 Link 1 -->
  <xacro:leg_joint
    name="joint_leg0_motor0_link1"
    parent="base_link"
    child="leg0_motor0_link1" >
    <origin
      xyz="-0.12 0.175 0"
      rpy="3.14159265 -1.51843644924 0" />
    <axis
      xyz="0 0 -1" />
    <limit
      lower="-10000"
      upper="10000"
      effort="1000"
      velocity="1000" />
  </xacro:leg_joint>

  <!-- Leg 0 Motor 0 Link 2 -->
  <xacro:leg_joint
    name="joint_leg0_motor0_link2"
    parent="leg0_motor0_link1"
    child="leg0_motor0_link2" >
    <origin
      xyz="0 -0.09 0.01"
      rpy="0 0 4.11499265359" />
    <axis
      xyz="0 0 1" />
    <limit
      lower="-10000"
      upper="10000"
      effort="0"
      velocity="0" />
  </xacro:leg_joint>

  <!-- Leg 0 Motor 1 Link 1 -->
  <xacro:leg_joint
    name="joint_leg0_motor1_link1"
    parent="base_link"
    child="leg0_motor1_link1" >
    <origin
      xyz="-0.12 0.175 0"
      rpy="0 -1.51843644924 0" />
    <axis
      xyz="0 0 -1" />
    <limit
      lower="-10000"
      upper="10000"
      effort="1000"
      velocity="1000" />
  </xacro:leg_joint>

  <!-- Leg 0 Motor 1 Link 2 -->
  <xacro:leg_joint
    name="joint_leg0_motor1_link2"
    parent="leg0_motor1_link1"
    child="leg0_motor1_link2" >
    <origin
      xyz="0 -0.09 0.01"
      rpy="0 0 4.11499265359" />
    <axis
      xyz="0 0 1" />
    <limit
      lower="-10000"
      upper="10000"
      effort="0"
      velocity="0" />
  </xacro:leg_joint>




  <!-- Leg 1 Motor 0 Link 1 -->
  <xacro:leg_joint
    name="joint_leg1_motor0_link1"
    parent="base_link"
    child="leg1_motor0_link1" >
    <origin
      xyz="-0.12 -0.175 0"
      rpy="3.14159265 -1.51843644924 0" />
    <axis
      xyz="0 0 1" />
    <limit
      lower="-10000"
      upper="10000"
      effort="1000"
      velocity="1000" />
  </xacro:leg_joint>

  <!-- Leg 1 Motor 0 Link 2 -->
  <xacro:leg_joint
    name="joint_leg1_motor0_link2"
    parent="leg1_motor0_link1"
    child="leg1_motor0_link2" >
    <origin
      xyz="0 -0.09 -0.01"
      rpy="0 0 4.11499265359" />
    <axis
      xyz="0 0 1" />
    <limit
      lower="-10000"
      upper="10000"
      effort="0"
      velocity="0" />
  </xacro:leg_joint>

  <!-- Leg 1 Motor 1 Link 1 -->
  <xacro:leg_joint
    name="joint_leg1_motor1_link1"
    parent="base_link"
    child="leg1_motor1_link1" >
    <origin
      xyz="-0.12 -0.175 0"
      rpy="0 -1.51843644924 0" />
    <axis
      xyz="0 0 1" />
    <limit
      lower="-10000"
      upper="10000"
      effort="1000"
      velocity="1000" />
  </xacro:leg_joint>

  <!-- Leg 1 Motor 1 Link 2 -->
  <xacro:leg_joint
    name="joint_leg1_motor1_link2"
    parent="leg1_motor1_link1"
    child="leg1_motor1_link2" >
    <origin
      xyz="0 -0.09 -0.01"
      rpy="0 0 4.11499265359" />
    <axis
      xyz="0 0 1" />
    <limit
      lower="-10000"
      upper="10000"
      effort="0"
      velocity="0" />
  </xacro:leg_joint>





  <!-- Leg 2 Motor 0 Link 1 -->
  <xacro:leg_joint
    name="joint_leg2_motor1_link1"
    parent="base_link"
    child="leg2_motor1_link1" >
    <origin
      xyz="0.12 -0.175 0"
      rpy="3.14159265 -1.62315620435 0" />
    <axis
      xyz="0 0 -1" />
    <limit
      lower="-10000"
      upper="10000"
      effort="1000"
      velocity="1000" />
  </xacro:leg_joint>

  <!-- Leg 2 Motor 0 Link 2 -->
  <xacro:leg_joint
    name="joint_leg2_motor1_link2"
    parent="leg2_motor1_link1"
    child="leg2_motor1_link2" >
    <origin
      xyz="0 -0.09 0.01"
      rpy="0 0 4.11499265359" />
    <axis
      xyz="0 0 1" />
    <limit
      lower="-10000"
      upper="10000"
      effort="0"
      velocity="0" />
  </xacro:leg_joint>

  <!-- Leg 2 Motor 1 Link 1 -->
  <xacro:leg_joint
    name="joint_leg2_motor0_link1"
    parent="base_link"
    child="leg2_motor0_link1" >
    <origin
      xyz="0.12 -0.175 0"
      rpy="0 -1.62315620435 0" />
    <axis
      xyz="0 0 -1" />
    <limit
      lower="-10000"
      upper="10000"
      effort="1000"
      velocity="1000" />
  </xacro:leg_joint>

  <!-- Leg 2 Motor 1 Link 2 -->
  <xacro:leg_joint
    name="joint_leg2_motor0_link2"
    parent="leg2_motor0_link1"
    child="leg2_motor0_link2" >
    <origin
      xyz="0 -0.09 0.01"
      rpy="0 0 4.11499265359" />
    <axis
      xyz="0 0 1" />
    <limit
      lower="-10000"
      upper="10000"
      effort="0"
      velocity="0" />
  </xacro:leg_joint>




  <!-- Leg 3 Motor 0 Link 1 -->
  <xacro:leg_joint
    name="joint_leg3_motor0_link1"
    parent="base_link"
    child="leg3_motor0_link1" >
    <origin
      xyz="0.12 0.175 0"
      rpy="0 -1.62315620435 0" />
    <axis
      xyz="0 0 1" />
    <limit
      lower="-10000"
      upper="10000"
      effort="1000"
      velocity="1000" />
  </xacro:leg_joint>

  <!-- Leg 3 Motor 0 Link 2 -->
  <xacro:leg_joint
    name="joint_leg3_motor0_link2"
    parent="leg3_motor0_link1"
    child="leg3_motor0_link2" >
    <origin
      xyz="0 -0.09 -0.01"
      rpy="0 0 4.11499265359" />
    <axis
      xyz="0 0 1" />
    <limit
      lower="-10000"
      upper="10000"
      effort="0"
      velocity="0" />
  </xacro:leg_joint>

  <!-- Leg 3 Motor 1 Link 1 -->
  <xacro:leg_joint
    name="joint_leg3_motor1_link1"
    parent="base_link"
    child="leg3_motor1_link1" >
    <origin
      xyz="0.12 0.175 0"
      rpy="3.14159265 -1.62315620435 0" />
    <axis
      xyz="0 0 1" />
    <limit
      lower="-10000"
      upper="10000"
      effort="1000"
      velocity="1000" />
  </xacro:leg_joint>

  <!-- Leg 3 Motor 1 Link 2 -->
  <xacro:leg_joint
    name="joint_leg3_motor1_link2"
    parent="leg3_motor1_link1"
    child="leg3_motor1_link2" >
    <origin
      xyz="0 -0.09 -0.01"
      rpy="0 0 4.11499265359" />
    <axis
      xyz="0 0 1" />
    <limit
      lower="-10000"
      upper="10000"
      effort="0"
      velocity="0" />
  </xacro:leg_joint>


  <gazebo>
    <joint name="joint_leg0_motor0_motor1_link2" type="revolute">
      <pose>0.0 -0.16 -0.01 0 0 0</pose>
      <axis>
        <xyz>0.9986 0 -0.0523</xyz> <!--XYZ relative to global axis, need to lower vector by 3deg to align with leg-->
        <limit>
          <lower>-10000</lower>
          <upper>10000</upper>
          <effort>0</effort>
          <velocity>0</velocity>
        </limit>
      </axis>
      <parent>leg0_motor0_link2</parent>
      <child>leg0_motor1_link2</child>
    </joint>
  </gazebo>

  <gazebo>
    <joint name="joint_leg1_motor0_motor1_link2" type="revolute">
      <pose>0.0 -0.16 0.01 0 0 0</pose>
      <axis>
        <xyz>0.9986 0 -0.0523</xyz> <!--XYZ relative to global axis, need to lower vector by 3deg to align with leg-->
        <limit>
          <lower>-10000</lower>
          <upper>10000</upper>
          <effort>0</effort>
          <velocity>0</velocity>
        </limit>
      </axis>
      <parent>leg1_motor0_link2</parent>
      <child>leg1_motor1_link2</child>
    </joint>
  </gazebo>

  <gazebo>
    <joint name="joint_leg2_motor0_motor1_link2" type="revolute">
      <pose>0.0 -0.16 -0.01 0 0 0</pose>
      <axis>
        <xyz>0.9986 0 0.0523</xyz> <!--XYZ relative to global axis, need to lower vector by 3deg to align with leg-->
        <limit>
          <lower>-10000</lower>
          <upper>10000</upper>
          <effort>0</effort>
          <velocity>0</velocity>
        </limit>
      </axis>
      <parent>leg2_motor0_link2</parent>
      <child>leg2_motor1_link2</child>
    </joint>
  </gazebo>

  <gazebo>
    <joint name="joint_leg3_motor0_motor1_link2" type="revolute">
      <pose>0.0 -0.16 0.01 0 0 0</pose>
      <axis>
        <xyz>0.9986 0 0.0523</xyz> <!--XYZ relative to global axis, need to lower vector by 3deg to align with leg-->
        <limit>
          <lower>-10000</lower>
          <upper>10000</upper>
          <effort>0</effort>
          <velocity>0</velocity>
        </limit>
      </axis>
      <parent>leg3_motor0_link2</parent>
      <child>leg3_motor1_link2</child>
    </joint>
  </gazebo>

  <link name="base_scan">
    <visual>
      <origin 
       xyz="0 0 0" 
       rpy="0 0 0"/>
      <geometry>
        <mesh filename="package://turtlebot3_description/meshes/sensors/lds.stl" scale="0.001 0.001 0.001"/>
      </geometry>
      <material name="dark"/>
    </visual>
    <collision>
      <origin xyz="0.015 0 -0.0065" rpy="0 0 0"/>
      <geometry>
        <cylinder length="0.0315" radius="0.055"/>
      </geometry>
    </collision>
    <inertial>
      <mass value="0.07308" />
      <origin xyz="0 0 0" />
      <inertia 
       ixx="3.1706E-05" 
       ixy="-6.531E-06" 
       ixz="-5.9512E-07"
       iyx="-6.531E-06"
       iyy="7.2012E-05" 
       iyz="3.7927E-07"
       izx="-5.9512E-07"
       izy="3.7927E-07"
       izz="6.1528E-05" />
    </inertial>
  </link>

  <joint name="scan_joint" type="fixed">
    <parent 
     link="base_link"/>
    <child 
     link="base_scan"/>
    <origin 
     xyz="0.0 0.0 0.12" 
     rpy="0 0 1.5707"/>
  </joint>

  <gazebo reference="base_scan">
    <material>Gazebo/FlatBlack</material>
    <sensor type="ray" name="lds_lfcd_sensor">
      <pose>0 0 0 0 0 0</pose>
      <visualize>$(arg laser_visual)</visualize>
      <update_rate>5</update_rate>
      <ray>
        <scan>
          <horizontal>
            <samples>360</samples>
            <resolution>1</resolution>
            <min_angle>0.0</min_angle>
            <max_angle>6.28319</max_angle>
          </horizontal>
        </scan>
        <range>
          <min>0.120</min>
          <max>4.0</max>
          <resolution>0.015</resolution>
        </range>
        <noise>
          <type>gaussian</type>
          <mean>0.0</mean>
          <stddev>0.01</stddev>
        </noise>
      </ray>
      <plugin name="gazebo_ros_lds_lfcd_controller" filename="libgazebo_ros_laser.so">
        <topicName>scan</topicName>
        <frameName>base_scan</frameName>
      </plugin>
    </sensor>
  </gazebo>

  <link name="camera_link">
    <collision>
      <origin 
       xyz="0 0.0175 0" 
       rpy="0 0 0"/>
      <geometry>
        <box size="0.02505 0.090 0.025"/>
      </geometry>
    </collision>
    <inertial>
      <mass value="0.0482"/>
      <origin 
       xyz="-0.00767 0 -0.00005" 
       rpy="0 0 0"/>
      <inertia 
       ixx="3.0309E-05" 
       ixy="1.2E-10" 
       ixz="3.72E-09"
       iyx="1.2E-10" 
       iyy="4.451E-06" 
       iyz="1.2E-10"
       izx="3.72E-09"
       izy="1.2E-10"
       izz="3.0582E-05" />
    </inertial>
    <visual name="visual">
      <origin 
        xyz="0 0 0" 
        rpy="1.5707 0 1.5707"/>
      <geometry>
        <mesh filename="package://realsense2_description/meshes/d435.dae"/>
      </geometry>
    </visual>
  </link>
  
  <joint name="camera_joint" type="fixed">
    <origin 
     xyz="0 0.06 0.25"  
     rpy="0 0 1.5707"/>
    <parent 
     link="base_link"/>
    <child 
     link="camera_link"/>
  </joint>

  <link name="camera_rgb_frame"/>

  <joint name="camera_rgb_joint" type="fixed">
    <origin xyz="0.003 0.011 0.009" rpy="0 0 0"/>
    <parent link="camera_link"/>
    <child link="camera_rgb_frame"/>
  </joint>
  
  <link name="camera_rgb_optical_frame"/>

  <joint name="camera_rgb_optical_joint" type="fixed">
    <origin xyz="0 0 0" rpy="-1.5707 0 -1.5707"/>
    <parent link="camera_rgb_frame"/>
    <child link="camera_rgb_optical_frame"/>
  </joint>

  <gazebo reference="camera_rgb_frame">
    <sensor type="depth" name="d435i_camera">
      <update_rate>20</update_rate>
      <always_on>true</always_on>
      <visualize>$(arg camera_visual)</visualize>
      <camera>
          <horizontal_fov>1.047198</horizontal_fov>
          <image>
              <width>640</width>
              <height>480</height>
              <format>R8G8B8</format>
          </image>
          <clip>
              <near>0.05</near>
              <far>8.0</far>
          </clip>
      </camera>
      <plugin name="kinect_camera_controller" filename="libgazebo_ros_openni_kinect.so">
        <alwaysOn>true</alwaysOn>
        <baseline>0.1</baseline >
        <updateRate>10</updateRate>
        <!--cameraName>camera_ir</cameraName -->
        <cameraName>camera</cameraName>
        <imageTopicName>/$(arg robot_name)/camera/color/image_raw</imageTopicName>
        <cameraInfoTopicName>/$(arg robot_name)/camera/color/camera_info</cameraInfoTopicName>
        <depthImageTopicName>/$(arg robot_name)/camera/depth/image_raw</depthImageTopicName>
        <depthImageCameraInfoTopicName>/$(arg robot_name)/camera/depth/camera_info</depthImageCameraInfoTopicName>
        <pointCloudTopicName>/$(arg robot_name)/camera/depth/points</pointCloudTopicName>
        <frameName>camera_rgb_optical_frame</frameName>
        <pointCloudCutoff>0.4</pointCloudCutoff>
        <distortionK1>0.0</distortionK1>
        <distortionK2>0.0</distortionK2>
        <distortionK3>0.0</distortionK3>
        <distortionT1>0.0</distortionT1>
        <distortionT2>0.0</distortionT2>
        <!--hackBaseline>0.1</hackBaseline-->  
      </plugin>
    </sensor>
  </gazebo>


  <xacro:m_transmission
    tran_name="tran_leg0_motor0"
    joint_name="joint_leg0_motor0_link1"
    acutator_name="leg0_motor0" />

  <xacro:m_transmission
    tran_name="tran_leg0_motor1"
    joint_name="joint_leg0_motor1_link1"
    acutator_name="leg0_motor1" />
  
  <xacro:m_transmission
    tran_name="tran_leg1_motor0"
    joint_name="joint_leg1_motor0_link1"
    acutator_name="leg1_motor0" />
  
  <xacro:m_transmission
    tran_name="tran_leg1_motor1"
    joint_name="joint_leg1_motor1_link1"
    acutator_name="leg1_motor1" />
  
  <xacro:m_transmission
    tran_name="tran_leg2_motor0"
    joint_name="joint_leg2_motor0_link1"
    acutator_name="leg2_motor1" />

  <xacro:m_transmission
    tran_name="tran_leg2_motor1"
    joint_name="joint_leg2_motor1_link1"
    acutator_name="leg2_motor1" />

  <xacro:m_transmission
    tran_name="tran_leg3_motor0"
    joint_name="joint_leg3_motor0_link1"
    acutator_name="leg0_motor1" />

  <xacro:m_transmission
    tran_name="tran_leg3_motor1"
    joint_name="joint_leg3_motor1_link1"
    acutator_name="leg3_motor1" />

  <!-- <transmission name="dummy_tran0">
    <type>transmission_interface/SimpleTransmission</type>
    <joint name="joint_dummy_to_base_link"><hardwareInterface>hardware_interface/EffortJointInterface</hardwareInterface></joint>
    <actuator name="dummy_motor0"><mechanicalReduction>1</mechanicalReduction></actuator>
  </transmission> -->
  <transmission name="dummy_tran1">
    <type>transmission_interface/SimpleTransmission</type>
    <joint name="joint_leg0_motor0_link2"><hardwareInterface>hardware_interface/EffortJointInterface</hardwareInterface></joint>
    <actuator name="dummy_motor1"><mechanicalReduction>1</mechanicalReduction></actuator>
  </transmission>
  <transmission name="dummy_tran2">
    <type>transmission_interface/SimpleTransmission</type>
    <joint name="joint_leg0_motor1_link2"><hardwareInterface>hardware_interface/EffortJointInterface</hardwareInterface></joint>
    <actuator name="dummy_motor2"><mechanicalReduction>1</mechanicalReduction></actuator>
  </transmission>
  <transmission name="dummy_tran3">
    <type>transmission_interface/SimpleTransmission</type>
    <joint name="joint_leg1_motor0_link2"><hardwareInterface>hardware_interface/EffortJointInterface</hardwareInterface></joint>
    <actuator name="dummy_motor3"><mechanicalReduction>1</mechanicalReduction></actuator>
  </transmission>
  <transmission name="dummy_tran4">
    <type>transmission_interface/SimpleTransmission</type>
    <joint name="joint_leg1_motor1_link2"><hardwareInterface>hardware_interface/EffortJointInterface</hardwareInterface></joint>
    <actuator name="dummy_motor4"><mechanicalReduction>1</mechanicalReduction></actuator>
  </transmission>
  <transmission name="dummy_tran5">
    <type>transmission_interface/SimpleTransmission</type>
    <joint name="joint_leg2_motor0_link2"><hardwareInterface>hardware_interface/EffortJointInterface</hardwareInterface></joint>
    <actuator name="dummy_motor5"><mechanicalReduction>1</mechanicalReduction></actuator>
  </transmission>
  <transmission name="dummy_tran6">
    <type>transmission_interface/SimpleTransmission</type>
    <joint name="joint_leg2_motor1_link2"><hardwareInterface>hardware_interface/EffortJointInterface</hardwareInterface></joint>
    <actuator name="dummy_motor6"><mechanicalReduction>1</mechanicalReduction></actuator>
  </transmission>
  <transmission name="dummy_tran7">
    <type>transmission_interface/SimpleTransmission</type>
    <joint name="joint_leg3_motor0_link2"><hardwareInterface>hardware_interface/EffortJointInterface</hardwareInterface></joint>
    <actuator name="dummy_motor7"><mechanicalReduction>1</mechanicalReduction></actuator>
  </transmission>
  <transmission name="dummy_tran8">
    <type>transmission_interface/SimpleTransmission</type>
    <joint name="joint_leg3_motor1_link2"><hardwareInterface>hardware_interface/EffortJointInterface</hardwareInterface></joint>
    <actuator name="dummy_motor8"><mechanicalReduction>1</mechanicalReduction></actuator>
  </transmission>

</robot>